[Mon Jun 13 21:13:00.627502 2016] [:error] [pid 12:tid 140439382136576] @@@@@ When query type is text, there are 2 possible classes:
[Mon Jun 13 21:13:00.627548 2016] [:error] [pid 12:tid 140439382136576] 0. class_CA -- needs to invoke ['CA']
[Mon Jun 13 21:13:00.627558 2016] [:error] [pid 12:tid 140439382136576] 1. class_QA -- needs to invoke ['QA']
[Mon Jun 13 21:13:00.627565 2016] [:error] [pid 12:tid 140439382136576] @@@@@ When query type is image, there are 1 possible classes:
[Mon Jun 13 21:13:00.627573 2016] [:error] [pid 12:tid 140439382136576] 0. class_IMM -- needs to invoke ['IMM']
[Mon Jun 13 21:13:00.627580 2016] [:error] [pid 12:tid 140439382136576] @@@@@ When query type is text_image, there are 3 possible classes:
[Mon Jun 13 21:13:00.627590 2016] [:error] [pid 12:tid 140439382136576] 0. class_IMM_QA -- needs to invoke ['IMM', 'QA']
[Mon Jun 13 21:13:00.627597 2016] [:error] [pid 12:tid 140439382136576] 1. class_QA -- needs to invoke ['QA']
[Mon Jun 13 21:13:00.627605 2016] [:error] [pid 12:tid 140439382136576] 2. class_IMM -- needs to invoke ['IMM']
[Mon Jun 13 21:13:01.547298 2016] [:error] [pid 12:tid 140439382136576] [remote 172.17.42.1:39325] mod_wsgi (pid=12): Target WSGI script '/usr/local/lucida/lucida/commandcenter/apache/apache.wsgi' cannot be loaded as Python module.
[Mon Jun 13 21:13:01.547366 2016] [:error] [pid 12:tid 140439382136576] [remote 172.17.42.1:39325] mod_wsgi (pid=12): Exception occurred processing WSGI script '/usr/local/lucida/lucida/commandcenter/apache/apache.wsgi'.
[Mon Jun 13 21:13:01.547420 2016] [:error] [pid 12:tid 140439382136576] [remote 172.17.42.1:39325] Traceback (most recent call last):
[Mon Jun 13 21:13:01.547461 2016] [:error] [pid 12:tid 140439382136576] [remote 172.17.42.1:39325]   File "/usr/local/lucida/lucida/commandcenter/apache/apache.wsgi", line 10, in <module>
[Mon Jun 13 21:13:01.547616 2016] [:error] [pid 12:tid 140439382136576] [remote 172.17.42.1:39325]     from app import app as application
[Mon Jun 13 21:13:01.547652 2016] [:error] [pid 12:tid 140439382136576] [remote 172.17.42.1:39325]   File "/usr/local/lucida/lucida/commandcenter/app.py", line 9, in <module>
[Mon Jun 13 21:13:01.547772 2016] [:error] [pid 12:tid 140439382136576] [remote 172.17.42.1:39325]     from controllers import *
[Mon Jun 13 21:13:01.547807 2016] [:error] [pid 12:tid 140439382136576] [remote 172.17.42.1:39325]   File "/usr/local/lucida/lucida/commandcenter/controllers/Infer.py", line 5, in <module>
[Mon Jun 13 21:13:01.547931 2016] [:error] [pid 12:tid 140439382136576] [remote 172.17.42.1:39325]     from QueryClassifier import query_classifier
[Mon Jun 13 21:13:01.547963 2016] [:error] [pid 12:tid 140439382136576] [remote 172.17.42.1:39325]   File "/usr/local/lucida/lucida/commandcenter/controllers/QueryClassifier.py", line 139, in <module>
[Mon Jun 13 21:13:01.548115 2016] [:error] [pid 12:tid 140439382136576] [remote 172.17.42.1:39325]     Config.CLASSIFIER_DESCRIPTIONS)
[Mon Jun 13 21:13:01.548152 2016] [:error] [pid 12:tid 140439382136576] [remote 172.17.42.1:39325]   File "/usr/local/lucida/lucida/commandcenter/controllers/QueryClassifier.py", line 43, in __init__
[Mon Jun 13 21:13:01.548212 2016] [:error] [pid 12:tid 140439382136576] [remote 172.17.42.1:39325]     self.CLASSIFIER_DESCRIPTIONS[input_type])
[Mon Jun 13 21:13:01.548242 2016] [:error] [pid 12:tid 140439382136576] [remote 172.17.42.1:39325]   File "/usr/local/lucida/lucida/commandcenter/controllers/QueryClassifier.py", line 101, in train
[Mon Jun 13 21:13:01.548297 2016] [:error] [pid 12:tid 140439382136576] [remote 172.17.42.1:39325]     'wb') as fid:
[Mon Jun 13 21:13:01.548340 2016] [:error] [pid 12:tid 140439382136576] [remote 172.17.42.1:39325] IOError: [Errno 13] Permission denied: '/usr/local/lucida/lucida/commandcenter/models/dumped_classifier_text.pkl'
[Mon Jun 13 21:13:01.731481 2016] [:error] [pid 12:tid 140439264532224] [remote 172.17.42.1:63887] mod_wsgi (pid=12): Target WSGI script '/usr/local/lucida/lucida/commandcenter/apache/apache.wsgi' cannot be loaded as Python module.
[Mon Jun 13 21:13:01.731507 2016] [:error] [pid 12:tid 140439264532224] [remote 172.17.42.1:63887] mod_wsgi (pid=12): Exception occurred processing WSGI script '/usr/local/lucida/lucida/commandcenter/apache/apache.wsgi'.
[Mon Jun 13 21:13:01.731533 2016] [:error] [pid 12:tid 140439264532224] [remote 172.17.42.1:63887] Traceback (most recent call last):
[Mon Jun 13 21:13:01.731561 2016] [:error] [pid 12:tid 140439264532224] [remote 172.17.42.1:63887]   File "/usr/local/lucida/lucida/commandcenter/apache/apache.wsgi", line 10, in <module>
[Mon Jun 13 21:13:01.731610 2016] [:error] [pid 12:tid 140439264532224] [remote 172.17.42.1:63887]     from app import app as application
[Mon Jun 13 21:13:01.731625 2016] [:error] [pid 12:tid 140439264532224] [remote 172.17.42.1:63887]   File "/usr/local/lucida/lucida/commandcenter/app.py", line 9, in <module>
[Mon Jun 13 21:13:01.731666 2016] [:error] [pid 12:tid 140439264532224] [remote 172.17.42.1:63887]     from controllers import *
[Mon Jun 13 21:13:01.731678 2016] [:error] [pid 12:tid 140439264532224] [remote 172.17.42.1:63887]   File "/usr/local/lucida/lucida/commandcenter/controllers/Infer.py", line 5, in <module>
[Mon Jun 13 21:13:01.731722 2016] [:error] [pid 12:tid 140439264532224] [remote 172.17.42.1:63887]     from QueryClassifier import query_classifier
[Mon Jun 13 21:13:01.731733 2016] [:error] [pid 12:tid 140439264532224] [remote 172.17.42.1:63887]   File "/usr/local/lucida/lucida/commandcenter/controllers/QueryClassifier.py", line 139, in <module>
[Mon Jun 13 21:13:01.731774 2016] [:error] [pid 12:tid 140439264532224] [remote 172.17.42.1:63887]     Config.CLASSIFIER_DESCRIPTIONS)
[Mon Jun 13 21:13:01.731785 2016] [:error] [pid 12:tid 140439264532224] [remote 172.17.42.1:63887]   File "/usr/local/lucida/lucida/commandcenter/controllers/QueryClassifier.py", line 43, in __init__
[Mon Jun 13 21:13:01.731825 2016] [:error] [pid 12:tid 140439264532224] [remote 172.17.42.1:63887]     self.CLASSIFIER_DESCRIPTIONS[input_type])
[Mon Jun 13 21:13:01.731836 2016] [:error] [pid 12:tid 140439264532224] [remote 172.17.42.1:63887]   File "/usr/local/lucida/lucida/commandcenter/controllers/QueryClassifier.py", line 101, in train
[Mon Jun 13 21:13:01.731873 2016] [:error] [pid 12:tid 140439264532224] [remote 172.17.42.1:63887]     'wb') as fid:
[Mon Jun 13 21:13:01.731899 2016] [:error] [pid 12:tid 140439264532224] [remote 172.17.42.1:63887] IOError: [Errno 13] Permission denied: '/usr/local/lucida/lucida/commandcenter/models/dumped_classifier_text.pkl'
[Mon Jun 13 21:13:08.270769 2016] [:error] [pid 12:tid 140439382136576] [remote 172.17.42.1:63887] mod_wsgi (pid=12): Target WSGI script '/usr/local/lucida/lucida/commandcenter/apache/apache.wsgi' cannot be loaded as Python module.
[Mon Jun 13 21:13:08.270797 2016] [:error] [pid 12:tid 140439382136576] [remote 172.17.42.1:63887] mod_wsgi (pid=12): Exception occurred processing WSGI script '/usr/local/lucida/lucida/commandcenter/apache/apache.wsgi'.
[Mon Jun 13 21:13:08.270831 2016] [:error] [pid 12:tid 140439382136576] [remote 172.17.42.1:63887] Traceback (most recent call last):
[Mon Jun 13 21:13:08.270853 2016] [:error] [pid 12:tid 140439382136576] [remote 172.17.42.1:63887]   File "/usr/local/lucida/lucida/commandcenter/apache/apache.wsgi", line 10, in <module>
[Mon Jun 13 21:13:08.270910 2016] [:error] [pid 12:tid 140439382136576] [remote 172.17.42.1:63887]     from app import app as application
[Mon Jun 13 21:13:08.270926 2016] [:error] [pid 12:tid 140439382136576] [remote 172.17.42.1:63887]   File "/usr/local/lucida/lucida/commandcenter/app.py", line 9, in <module>
[Mon Jun 13 21:13:08.270970 2016] [:error] [pid 12:tid 140439382136576] [remote 172.17.42.1:63887]     from controllers import *
[Mon Jun 13 21:13:08.270982 2016] [:error] [pid 12:tid 140439382136576] [remote 172.17.42.1:63887]   File "/usr/local/lucida/lucida/commandcenter/controllers/Infer.py", line 5, in <module>
[Mon Jun 13 21:13:08.271025 2016] [:error] [pid 12:tid 140439382136576] [remote 172.17.42.1:63887]     from QueryClassifier import query_classifier
[Mon Jun 13 21:13:08.271038 2016] [:error] [pid 12:tid 140439382136576] [remote 172.17.42.1:63887]   File "/usr/local/lucida/lucida/commandcenter/controllers/QueryClassifier.py", line 139, in <module>
[Mon Jun 13 21:13:08.271080 2016] [:error] [pid 12:tid 140439382136576] [remote 172.17.42.1:63887]     Config.CLASSIFIER_DESCRIPTIONS)
[Mon Jun 13 21:13:08.271092 2016] [:error] [pid 12:tid 140439382136576] [remote 172.17.42.1:63887]   File "/usr/local/lucida/lucida/commandcenter/controllers/QueryClassifier.py", line 43, in __init__
[Mon Jun 13 21:13:08.271131 2016] [:error] [pid 12:tid 140439382136576] [remote 172.17.42.1:63887]     self.CLASSIFIER_DESCRIPTIONS[input_type])
[Mon Jun 13 21:13:08.271143 2016] [:error] [pid 12:tid 140439382136576] [remote 172.17.42.1:63887]   File "/usr/local/lucida/lucida/commandcenter/controllers/QueryClassifier.py", line 101, in train
[Mon Jun 13 21:13:08.271183 2016] [:error] [pid 12:tid 140439382136576] [remote 172.17.42.1:63887]     'wb') as fid:
[Mon Jun 13 21:13:08.271214 2016] [:error] [pid 12:tid 140439382136576] [remote 172.17.42.1:63887] IOError: [Errno 13] Permission denied: '/usr/local/lucida/lucida/commandcenter/models/dumped_classifier_text.pkl'
[Mon Jun 13 21:13:08.454632 2016] [:error] [pid 12:tid 140439264532224] [remote 172.17.42.1:34205] mod_wsgi (pid=12): Target WSGI script '/usr/local/lucida/lucida/commandcenter/apache/apache.wsgi' cannot be loaded as Python module.
[Mon Jun 13 21:13:08.454648 2016] [:error] [pid 12:tid 140439264532224] [remote 172.17.42.1:34205] mod_wsgi (pid=12): Exception occurred processing WSGI script '/usr/local/lucida/lucida/commandcenter/apache/apache.wsgi'.
[Mon Jun 13 21:13:08.454671 2016] [:error] [pid 12:tid 140439264532224] [remote 172.17.42.1:34205] Traceback (most recent call last):
[Mon Jun 13 21:13:08.454686 2016] [:error] [pid 12:tid 140439264532224] [remote 172.17.42.1:34205]   File "/usr/local/lucida/lucida/commandcenter/apache/apache.wsgi", line 10, in <module>
[Mon Jun 13 21:13:08.454733 2016] [:error] [pid 12:tid 140439264532224] [remote 172.17.42.1:34205]     from app import app as application
[Mon Jun 13 21:13:08.454748 2016] [:error] [pid 12:tid 140439264532224] [remote 172.17.42.1:34205]   File "/usr/local/lucida/lucida/commandcenter/app.py", line 9, in <module>
[Mon Jun 13 21:13:08.454788 2016] [:error] [pid 12:tid 140439264532224] [remote 172.17.42.1:34205]     from controllers import *
[Mon Jun 13 21:13:08.454800 2016] [:error] [pid 12:tid 140439264532224] [remote 172.17.42.1:34205]   File "/usr/local/lucida/lucida/commandcenter/controllers/Infer.py", line 5, in <module>
[Mon Jun 13 21:13:08.454843 2016] [:error] [pid 12:tid 140439264532224] [remote 172.17.42.1:34205]     from QueryClassifier import query_classifier
[Mon Jun 13 21:13:08.454855 2016] [:error] [pid 12:tid 140439264532224] [remote 172.17.42.1:34205]   File "/usr/local/lucida/lucida/commandcenter/controllers/QueryClassifier.py", line 139, in <module>
[Mon Jun 13 21:13:08.454896 2016] [:error] [pid 12:tid 140439264532224] [remote 172.17.42.1:34205]     Config.CLASSIFIER_DESCRIPTIONS)
[Mon Jun 13 21:13:08.454908 2016] [:error] [pid 12:tid 140439264532224] [remote 172.17.42.1:34205]   File "/usr/local/lucida/lucida/commandcenter/controllers/QueryClassifier.py", line 43, in __init__
[Mon Jun 13 21:13:08.454949 2016] [:error] [pid 12:tid 140439264532224] [remote 172.17.42.1:34205]     self.CLASSIFIER_DESCRIPTIONS[input_type])
[Mon Jun 13 21:13:08.454961 2016] [:error] [pid 12:tid 140439264532224] [remote 172.17.42.1:34205]   File "/usr/local/lucida/lucida/commandcenter/controllers/QueryClassifier.py", line 101, in train
[Mon Jun 13 21:13:08.455000 2016] [:error] [pid 12:tid 140439264532224] [remote 172.17.42.1:34205]     'wb') as fid:
[Mon Jun 13 21:13:08.455022 2016] [:error] [pid 12:tid 140439264532224] [remote 172.17.42.1:34205] IOError: [Errno 13] Permission denied: '/usr/local/lucida/lucida/commandcenter/models/dumped_classifier_text.pkl'
[Mon Jun 13 21:13:09.275557 2016] [:error] [pid 12:tid 140439382136576] [remote 172.17.42.1:63887] mod_wsgi (pid=12): Target WSGI script '/usr/local/lucida/lucida/commandcenter/apache/apache.wsgi' cannot be loaded as Python module.
[Mon Jun 13 21:13:09.275584 2016] [:error] [pid 12:tid 140439382136576] [remote 172.17.42.1:63887] mod_wsgi (pid=12): Exception occurred processing WSGI script '/usr/local/lucida/lucida/commandcenter/apache/apache.wsgi'.
[Mon Jun 13 21:13:09.275607 2016] [:error] [pid 12:tid 140439382136576] [remote 172.17.42.1:63887] Traceback (most recent call last):
[Mon Jun 13 21:13:09.275625 2016] [:error] [pid 12:tid 140439382136576] [remote 172.17.42.1:63887]   File "/usr/local/lucida/lucida/commandcenter/apache/apache.wsgi", line 10, in <module>
[Mon Jun 13 21:13:09.275676 2016] [:error] [pid 12:tid 140439382136576] [remote 172.17.42.1:63887]     from app import app as application
[Mon Jun 13 21:13:09.275690 2016] [:error] [pid 12:tid 140439382136576] [remote 172.17.42.1:63887]   File "/usr/local/lucida/lucida/commandcenter/app.py", line 9, in <module>
[Mon Jun 13 21:13:09.275729 2016] [:error] [pid 12:tid 140439382136576] [remote 172.17.42.1:63887]     from controllers import *
[Mon Jun 13 21:13:09.275741 2016] [:error] [pid 12:tid 140439382136576] [remote 172.17.42.1:63887]   File "/usr/local/lucida/lucida/commandcenter/controllers/Infer.py", line 5, in <module>
[Mon Jun 13 21:13:09.275786 2016] [:error] [pid 12:tid 140439382136576] [remote 172.17.42.1:63887]     from QueryClassifier import query_classifier
[Mon Jun 13 21:13:09.275798 2016] [:error] [pid 12:tid 140439382136576] [remote 172.17.42.1:63887]   File "/usr/local/lucida/lucida/commandcenter/controllers/QueryClassifier.py", line 139, in <module>
[Mon Jun 13 21:13:09.275838 2016] [:error] [pid 12:tid 140439382136576] [remote 172.17.42.1:63887]     Config.CLASSIFIER_DESCRIPTIONS)
[Mon Jun 13 21:13:09.275850 2016] [:error] [pid 12:tid 140439382136576] [remote 172.17.42.1:63887]   File "/usr/local/lucida/lucida/commandcenter/controllers/QueryClassifier.py", line 43, in __init__
[Mon Jun 13 21:13:09.275892 2016] [:error] [pid 12:tid 140439382136576] [remote 172.17.42.1:63887]     self.CLASSIFIER_DESCRIPTIONS[input_type])
[Mon Jun 13 21:13:09.275904 2016] [:error] [pid 12:tid 140439382136576] [remote 172.17.42.1:63887]   File "/usr/local/lucida/lucida/commandcenter/controllers/QueryClassifier.py", line 101, in train
[Mon Jun 13 21:13:09.275943 2016] [:error] [pid 12:tid 140439382136576] [remote 172.17.42.1:63887]     'wb') as fid:
[Mon Jun 13 21:13:09.275969 2016] [:error] [pid 12:tid 140439382136576] [remote 172.17.42.1:63887] IOError: [Errno 13] Permission denied: '/usr/local/lucida/lucida/commandcenter/models/dumped_classifier_text.pkl'
[Mon Jun 13 21:13:09.446852 2016] [:error] [pid 12:tid 140439264532224] [remote 172.17.42.1:63887] mod_wsgi (pid=12): Target WSGI script '/usr/local/lucida/lucida/commandcenter/apache/apache.wsgi' cannot be loaded as Python module.
[Mon Jun 13 21:13:09.446870 2016] [:error] [pid 12:tid 140439264532224] [remote 172.17.42.1:63887] mod_wsgi (pid=12): Exception occurred processing WSGI script '/usr/local/lucida/lucida/commandcenter/apache/apache.wsgi'.
[Mon Jun 13 21:13:09.446893 2016] [:error] [pid 12:tid 140439264532224] [remote 172.17.42.1:63887] Traceback (most recent call last):
[Mon Jun 13 21:13:09.446912 2016] [:error] [pid 12:tid 140439264532224] [remote 172.17.42.1:63887]   File "/usr/local/lucida/lucida/commandcenter/apache/apache.wsgi", line 10, in <module>
[Mon Jun 13 21:13:09.446961 2016] [:error] [pid 12:tid 140439264532224] [remote 172.17.42.1:63887]     from app import app as application
[Mon Jun 13 21:13:09.446975 2016] [:error] [pid 12:tid 140439264532224] [remote 172.17.42.1:63887]   File "/usr/local/lucida/lucida/commandcenter/app.py", line 9, in <module>
[Mon Jun 13 21:13:09.447013 2016] [:error] [pid 12:tid 140439264532224] [remote 172.17.42.1:63887]     from controllers import *
[Mon Jun 13 21:13:09.447025 2016] [:error] [pid 12:tid 140439264532224] [remote 172.17.42.1:63887]   File "/usr/local/lucida/lucida/commandcenter/controllers/Infer.py", line 5, in <module>
[Mon Jun 13 21:13:09.447065 2016] [:error] [pid 12:tid 140439264532224] [remote 172.17.42.1:63887]     from QueryClassifier import query_classifier
[Mon Jun 13 21:13:09.447077 2016] [:error] [pid 12:tid 140439264532224] [remote 172.17.42.1:63887]   File "/usr/local/lucida/lucida/commandcenter/controllers/QueryClassifier.py", line 139, in <module>
[Mon Jun 13 21:13:09.447116 2016] [:error] [pid 12:tid 140439264532224] [remote 172.17.42.1:63887]     Config.CLASSIFIER_DESCRIPTIONS)
[Mon Jun 13 21:13:09.447128 2016] [:error] [pid 12:tid 140439264532224] [remote 172.17.42.1:63887]   File "/usr/local/lucida/lucida/commandcenter/controllers/QueryClassifier.py", line 43, in __init__
[Mon Jun 13 21:13:09.447167 2016] [:error] [pid 12:tid 140439264532224] [remote 172.17.42.1:63887]     self.CLASSIFIER_DESCRIPTIONS[input_type])
[Mon Jun 13 21:13:09.447179 2016] [:error] [pid 12:tid 140439264532224] [remote 172.17.42.1:63887]   File "/usr/local/lucida/lucida/commandcenter/controllers/QueryClassifier.py", line 101, in train
[Mon Jun 13 21:13:09.447220 2016] [:error] [pid 12:tid 140439264532224] [remote 172.17.42.1:63887]     'wb') as fid:
[Mon Jun 13 21:13:09.447243 2016] [:error] [pid 12:tid 140439264532224] [remote 172.17.42.1:63887] IOError: [Errno 13] Permission denied: '/usr/local/lucida/lucida/commandcenter/models/dumped_classifier_text.pkl'
